Workbook

Sheet Customer Names
A1: Customer ID | B1: Title | C1: First name | D1: Last name
A2: Id1 | B2: Hawks | C2: Kelly
A3: Id2 | B3: Lehner | C3: Matthew | D3: D
A4: Id3 | B4: Lu | C4: Phil
A5: Id4 | B5: Osborne | C5: Kelsey
A6: Id5 | B6: Kadala | C6: Kristyn
A7: Id6 | B7: Baker | C7: Russell | D7: B.
A8: Id7 | B8: Macpherson | C8: Scott
A9: Id8 | B9: Hallman | C9: Stephen
A10: Id9 | B10: Moran | C10: Patrick | D10: R.
A11: Id10 | B11: Benner | C11: Brooke | D11: N.
A12: Id11 | B12: Fierro Vargas | C12: Paola | D12: Andrea
A13: Id12 | B13: Franz | C13: David
A14: Id13 | B14: Foster | C14: Wade
A15: Id14 | B15: Tenorio | C15: Franklin
A16: Id15 | B16: Rios | C16: Leilani | D16: M.
A17: Id16 | B17: Viau-Dupuis | C17: Philippe
A18: Id17 | B18: Cronin | C18: Jennifer | D18: A.
A19: Id18 | B19: Noordstar | C19: Christina | D19: M.
A20: Id19 | B20: Boudalia | C20: Said | D20: Sr.
A21: Id20 | B21: Flor | C21: John
A22: Id21 | B22: Fennon | C22: Myles
A23: Id22 | B23: Hribar | C23: Madelyn | D23: C
A24: Id23 | B24: Tassello | C24: Nicole
A25: Id24 | B25: Mauricette | C25: Eric | D25: A.
A26: Id25 | B26: Garcia | C26: Emiliano | D26: I.
A27: Id26 | B27: Airoldi | C27: Adam
A28: Id27 | B28: Cater-Cyker | C28: Zach
A29: Id28 | B29: Hamm | C29: Stephanie | D29: W.
A30: Id29 | B30: Cox | C30: Stephen
A31: Id30 | B31: Sachrajda | C31: Natalie
A32: Id31 | B32: Gareri | C32: Nicole | D32: J.
A33: Id32 | B33: Welch | C33: Jefferson | D33: D
A34: Id33 | B34: Prindiville | C34: Brendan | D34: D.
A35: Id34 | B35: Kincaid | C35: Courtney
A36: Id35 | B36: Bruestle | C36: Sydney | D36: L.
A37: Id36 | B37: Lachance | C37: Julien
A38: Id37 | B38: Eason | C38: Ryan | D38: M
A39: Id38 | B39: Grummon | C39: Anna | D39: H.
A40: Id39 | B40: Vanwechel | C40: Samantha
...

Sheet Table1
A1: Customer ID | B1: Date of birth | C1: children | D1: charges | E1: Hospital tier | F1: City tier | G1: State ID | H1: new state id | I1: age
A2: Id2335 | B2: 33786 | D2: 563.84 | E2: tier - 2 | F2: tier - 3 | G2: R1013 | H2: R1013 | I2: =DATEDIF(Table1_1[[#This Row],[Date of birth]],TODAY(),"Y") -> 32
A3: Id2334 | B3: 33938 | D3: 570.62 | E3: tier - 2 | F3: tier - 1 | G3: R1013 | H3: R1013 | I3: =DATEDIF(Table1_1[[#This Row],[Date of birth]],TODAY(),"Y") -> 32
A4: Id2333 | B4: 34150 | D4: 600 | E4: tier - 2 | F4: tier - 1 | G4: R1013 | H4: R1013 | I4: =DATEDIF(Table1_1[[#This Row],[Date of birth]],TODAY(),"Y") -> 31
A5: Id2332 | B5: 33860 | D5: 604.54 | E5: tier - 3 | F5: tier - 3 | G5: R1013 | H5: R1013 | I5: =DATEDIF(Table1_1[[#This Row],[Date of birth]],TODAY(),"Y") -> 32
A6: Id2331 | B6: 36003 | D6: 637.26 | E6: tier - 3 | F6: tier - 3 | G6: R1013 | H6: R1013 | I6: =DATEDIF(Table1_1[[#This Row],[Date of birth]],TODAY(),"Y") -> 26
A7: Id2330 | B7: 37215 | D7: 646.14 | E7: tier - 3 | F7: tier - 3 | G7: R1012 | H7: R1012 | I7: =DATEDIF(Table1_1[[#This Row],[Date of birth]],TODAY(),"Y") -> 23
A8: Id2329 | B8: 34121 | D8: 650 | E8: tier - 3 | F8: tier - 3 | G8: R1013 | H8: R1013 | I8: =DATEDIF(Table1_1[[#This Row],[Date of birth]],TODAY(),"Y") -> 31
A9: Id2328 | B9: 34881 | D9: 650 | E9: tier - 3 | F9: tier - 3 | G9: R1013 | H9: R1013 | I9: =DATEDIF(Table1_1[[#This Row],[Date of birth]],TODAY(),"Y") -> 29
A10: Id2327 | B10: 37589 | D10: 668 | E10: tier - 3 | F10: tier - 2 | G10: R1012 | H10: R1012 | I10: =DATEDIF(Table1_1[[#This Row],[Date of birth]],TODAY(),"Y") -> 22
A11: Id2326 | B11: 35735 | D11: 670 | E11: tier - 3 | F11: tier - 3 | G11: R1013 | H11: R1013 | I11: =DATEDIF(Table1_1[[#This Row],[Date of birth]],TODAY(),"Y") -> 27
A12: Id2325 | B12: 37146 | D12: 687.54 | E12: tier - 3 | F12: tier - 2 | G12: R1013 | H12: R1013 | I12: =DATEDIF(Table1_1[[#This Row],[Date of birth]],TODAY(),"Y") -> 23
A13: Id2324 | B13: 36520 | D13: 700 | F13: tier - 3 | G13: R1013 | H13: R1013 | I13: =DATEDIF(Table1_1[[#This Row],[Date of birth]],TODAY(),"Y") -> 25
A14: Id2323 | B14: 36508 | D14: 722.99 | E14: tier - 3 | F14: tier - 1 | G14: R1013 | H14: R1013 | I14: =DATEDIF(Table1_1[[#This Row],[Date of birth]],TODAY(),"Y") -> 25
A15: Id2322 | B15: 37518 | D15: 750 | E15: tier - 3 | F15: tier - 1 | G15: R1012 | H15: R1012 | I15: =DATEDIF(Table1_1[[#This Row],[Date of birth]],TODAY(),"Y") -> 22
A16: Id2321 | B16: 34182 | D16: 760 | E16: tier - 3 | F16: tier - 1 | G16: R1013 | H16: R1013 | I16: =DATEDIF(Table1_1[[#This Row],[Date of birth]],TODAY(),"Y") -> 31
A17: Id2320 | B17: 35360 | D17: 760 | E17: tier - 3 | F17: tier - 3 | G17: R1013 | H17: R1013 | I17: =DATEDIF(Table1_1[[#This Row],[Date of birth]],TODAY(),"Y") -> 28
A18: Id2319 | B18: 34148 | D18: 770 | E18: tier - 3 | F18: tier - 3 | G18: R1013 | H18: R1013 | I18: =DATEDIF(Table1_1[[#This Row],[Date of birth]],TODAY(),"Y") -> 31
A19: Id2318 | B19: 35326 | D19: 770.38 | E19: tier - 3 | G19: R1012 | H19: R1012 | I19: =DATEDIF(Table1_1[[#This Row],[Date of birth]],TODAY(),"Y") -> 28
A20: Id2317 | B20: 35034 | D20: 773.54 | E20: tier - 3 | F20: tier - 2 | G20: R1013 | H20: R1013 | I20: =DATEDIF(Table1_1[[#This Row],[Date of birth]],TODAY(),"Y") -> 29
A21: Id2316 | B21: 38261 | D21: 830.52 | E21: tier - 3 | F21: tier - 2 | G21: R1011 | H21: R1011 | I21: =DATEDIF(Table1_1[[#This Row],[Date of birth]],TODAY(),"Y") -> 20
A22: Id2315 | B22: 36848 | D22: 865.41 | E22: tier - 3 | F22: tier - 1 | G22: R1013 | H22: R1013 | I22: =DATEDIF(Table1_1[[#This Row],[Date of birth]],TODAY(),"Y") -> 24
A23: Id2314 | B23: 34300 | D23: 896.21 | E23: tier - 3 | F23: tier - 1 | G23: R1013 | H23: R1013 | I23: =DATEDIF(Table1_1[[#This Row],[Date of birth]],TODAY(),"Y") -> 31
A24: Id2313 | B24: 34637 | D24: 915.07 | E24: tier - 3 | F24: tier - 1 | G24: R1013 | H24: R1013 | I24: =DATEDIF(Table1_1[[#This Row],[Date of birth]],TODAY(),"Y") -> 30
A25: Id2312 | B25: 35000 | D25: 928.59 | E25: tier - 3 | F25: tier - 1 | G25: R1013 | H25: R1013 | I25: =DATEDIF(Table1_1[[#This Row],[Date of birth]],TODAY(),"Y") -> 29
A26: Id2311 | B26: 37122 | D26: 964.71 | E26: tier - 3 | F26: tier - 2 | G26: R1013 | H26: R1013 | I26: =DATEDIF(Table1_1[[#This Row],[Date of birth]],TODAY(),"Y") -> 23
A27: Id2310 | B27: 34660 | D27: 1006.65 | E27: tier - 3 | F27: tier - 2 | G27: R1013 | H27: R1013 | I27: =DATEDIF(Table1_1[[#This Row],[Date of birth]],TODAY(),"Y") -> 30
A28: Id2309 | B28: 36800 | D28: 1012 | E28: tier - 3 | F28: tier - 2 | G28: R1013 | H28: R1013 | I28: =DATEDIF(Table1_1[[#This Row],[Date of birth]],TODAY(),"Y") -> 24
A29: Id2308 | B29: 36373 | D29: 1019 | E29: tier - 3 | F29: tier - 2 | G29: R1013 | H29: R1013 | I29: =DATEDIF(Table1_1[[#This Row],[Date of birth]],TODAY(),"Y") -> 25
A30: Id2307 | B30: 34973 | D30: 1033.74 | E30: tier - 3 | F30: tier - 1 | G30: R1013 | H30: R1013 | I30: =DATEDIF(Table1_1[[#This Row],[Date of birth]],TODAY(),"Y") -> 29
A31: Id2306 | B31: 34655 | D31: 1044 | E31: tier - 3 | F31: tier - 2 | G31: R1013 | H31: R1013 | I31: =DATEDIF(Table1_1[[#This Row],[Date of birth]],TODAY(),"Y") -> 30
... A46: Id2291 | B46: 37479 | D46: 1137 | E46: tier - 3 | F46: tier - 1 | G46: R1013 | H46: R1013 | I46: =DATEDIF(Table1_1[[#This Row],[Date of birth]],TODAY(),"Y") -> 22
B47: 38292 | D47: 1137.01 | E47: tier - 3 | F47: tier - 1 | G47: R1013 | H47: R1013 | I47: =DATEDIF(Table1_1[[#This Row],[Date of birth]],TODAY(),"Y") -> 20
A48: Id2290 | B48: 38275 | D48: 1137.01 | E48: tier - 3 | F48: tier - 1 | G48: R1013 | H48: R1013 | I48: =DATEDIF(Table1_1[[#This Row],[Date of birth]],TODAY(),"Y") -> 20
A49: Id2289 | B49: 38318 | D49: 1137.47 | E49: tier - 3 | F49: tier - 2 | G49: R1013 | H49: R1013 | I49: =DATEDIF(Table1_1[[#This Row],[Date of birth]],TODAY(),"Y") -> 20
A50: Id2288 | B50: 37189 | D50: 1141 | E50: tier - 3 | F50: tier - 1 | G50: R1013 | H50: R1013 | I50: =DATEDIF(Table1_1[[#This Row],[Date of birth]],TODAY(),"Y") -> 23
A51: Id2287 | B51: 38242 | D51: 1141.45 | E51: tier - 3 | F51: tier - 3 | G51: R1013 | H51: R1013 | I51: =DATEDIF(Table1_1[[#This Row],[Date of birth]],TODAY(),"Y") -> 20
A52: Id2286 | B52: 37530 | D52: 1142 | E52: tier - 3 | F52: tier - 2 | G52: R1011 | H52: R1011 | I52: =DATEDIF(Table1_1[[#This Row],[Date of birth]],TODAY(),"Y") -> 22
A53: Id2285 | B53: 38148 | D53: 1146.8 | E53: tier - 2 | F53: tier - 2 | G53: R1013 | H53: R1013 | I53: =DATEDIF(Table1_1[[#This Row],[Date of birth]],TODAY(),"Y") -> 20
A54: Id2284 | B54: 37784 | D54: 1149 | E54: tier - 2 | F54: tier - 1 | G54: R1012 | H54: R1012 | I54: =DATEDIF(Table1_1[[#This Row],[Date of birth]],TODAY(),"Y") -> 21
...

Sheet Hospitalisation Details
A1: Customer ID | B1: year | C1: month | D1: date | E1: children | F1: currency | G1: Hospital tier | H1: City tier | I1: State ID | J1: new state id
A2: Id2335 | B2: 1992 | C2: Jul | F2: 563.84 | G2: tier - 2 | H2: tier - 3 | I2: R1013 | J2: =IF(ISBLANK('Hospitalisation Details'!I2),"unkown",'Hospitalisation Details'!I2) -> R1013
A3: Id2334 | B3: 1992 | C3: Nov | D3: 30 | F3: 570.62 | G3: tier - 2 | H3: tier - 1 | I3: R1013 | J3: =IF(ISBLANK('Hospitalisation Details'!I3),"unkown",'Hospitalisation Details'!I3) -> R1013
A4: Id2333 | B4: 1993 | C4: Jun | D4: 30 | F4: 600 | G4: tier - 2 | H4: tier - 1 | I4: R1013 | J4: =IF(ISBLANK('Hospitalisation Details'!I4),"unkown",'Hospitalisation Details'!I4) -> R1013
A5: Id2332 | B5: 1992 | C5: Sep | D5: 13 | F5: 604.54 | G5: tier - 3 | H5: tier - 3 | I5: R1013 | J5: =IF(ISBLANK('Hospitalisation Details'!I5),"unkown",'Hospitalisation Details'!I5) -> R1013
A6: Id2331 | B6: 1998 | C6: Jul | D6: 27 | F6: 637.26 | G6: tier - 3 | H6: tier - 3 | I6: R1013 | J6: =IF(ISBLANK('Hospitalisation Details'!I6),"unkown",'Hospitalisation Details'!I6) -> R1013
A7: Id2330 | B7: 2001 | C7: Nov | D7: 20 | F7: 646.14 | G7: tier - 3 | H7: tier - 3 | I7: R1012 | J7: =IF(ISBLANK('Hospitalisation Details'!I7),"unkown",'Hospitalisation Details'!I7) -> R1012
A8: Id2329 | B8: 1993 | C8: Jun | F8: 650 | G8: tier - 3 | H8: tier - 3 | I8: R1013 | J8: =IF(ISBLANK('Hospitalisation Details'!I8),"unkown",'Hospitalisation Details'!I8) -> R1013
A9: Id2328 | B9: 1995 | C9: Jul | F9: 650 | G9: tier - 3 | H9: tier - 3 | I9: R1013 | J9: =IF(ISBLANK('Hospitalisation Details'!I9),"unkown",'Hospitalisation Details'!I9) -> R1013
A10: Id2327 | B10: 2002 | C10: Nov | D10: 29 | F10: 668 | G10: tier - 3 | H10: tier - 2 | I10: R1012 | J10: =IF(ISBLANK('Hospitalisation Details'!I10),"unkown",'Hospitalisation Details'!I10) -> R1012
A11: Id2326 | B11: 1997 | C11: Nov | F11: 670 | G11: tier - 3 | H11: tier - 3 | I11: R1013 | J11: =IF(ISBLANK('Hospitalisation Details'!I11),"unkown",'Hospitalisation Details'!I11) -> R1013
A12: Id2325 | B12: 2001 | C12: Sep | D12: 12 | F12: 687.54 | G12: tier - 3 | H12: tier - 2 | I12: R1013 | J12: =IF(ISBLANK('Hospitalisation Details'!I12),"unkown",'Hospitalisation Details'!I12) -> R1013
A13: Id2324 | B13: 1999 | C13: Dec | D13: 26 | F13: 700 | H13: tier - 3 | I13: R1013 | J13: =IF(ISBLANK('Hospitalisation Details'!I13),"unkown",'Hospitalisation Details'!I13) -> R1013
A14: Id2323 | B14: 1999 | C14: Dec | D14: 14 | F14: 722.99 | G14: tier - 3 | H14: tier - 1 | I14: R1013 | J14: =IF(ISBLANK('Hospitalisation Details'!I14),"unkown",'Hospitalisation Details'!I14) -> R1013
A15: Id2322 | B15: 2002 | C15: sep | D15: 19 | F15: 750 | G15: tier - 3 | H15: tier - 1 | I15: R1012 | J15: =IF(ISBLANK('Hospitalisation Details'!I15),"unkown",'Hospitalisation Details'!I15) -> R1012
A16: Id2321 | B16: 1993 | C16: Aug | F16: 760 | G16: tier - 3 | H16: tier - 1 | I16: R1013 | J16: =IF(ISBLANK('Hospitalisation Details'!I16),"unkown",'Hospitalisation Details'!I16) -> R1013
A17: Id2320 | B17: 1996 | C17: Oct | D17: 22 | F17: 760 | G17: tier - 3 | H17: tier - 3 | I17: R1013 | J17: =IF(ISBLANK('Hospitalisation Details'!I17),"unkown",'Hospitalisation Details'!I17) -> R1013
A18: Id2319 | B18: 1993 | C18: Jun | D18: 28 | F18: 770 | G18: tier - 3 | H18: tier - 3 | I18: R1013 | J18: =IF(ISBLANK('Hospitalisation Details'!I18),"unkown",'Hospitalisation Details'!I18) -> R1013
A19: Id2318 | B19: 1996 | C19: sep | D19: 18 | F19: 770.38 | G19: tier - 3 | I19: R1012 | J19: =IF(ISBLANK('Hospitalisation Details'!I19),"unkown",'Hospitalisation Details'!I19) -> R1012
A20: Id2317 | B20: 1995 | C20: Dec | F20: 773.54 | G20: tier - 3 | H20: tier - 2 | I20: R1013 | J20: =IF(ISBLANK('Hospitalisation Details'!I20),"unkown",'Hospitalisation Details'!I20) -> R1013
A21: Id2316 | B21: 2004 | C21: Oct | F21: 830.52 | G21: tier - 3 | H21: tier - 2 | I21: R1011 | J21: =IF(ISBLANK('Hospitalisation Details'!I21),"unkown",'Hospitalisation Details'!I21) -> R1011
A22: Id2315 | B22: 2000 | C22: Nov | D22: 18 | F22: 865.41 | G22: tier - 3 | H22: tier - 1 | I22: R1013 | J22: =IF(ISBLANK('Hospitalisation Details'!I22),"unkown",'Hospitalisation Details'!I22) -> R1013
A23: Id2314 | B23: 1993 | C23: Nov | D23: 27 | F23: 896.21 | G23: tier - 3 | H23: tier - 1 | I23: R1013 | J23: =IF(ISBLANK('Hospitalisation Details'!I23),"unkown",'Hospitalisation Details'!I23) -> R1013
A24: Id2313 | B24: 1994 | C24: Oct | D24: 30 | F24: 915.07 | G24: tier - 3 | H24: tier - 1 | I24: R1013 | J24: =IF(ISBLANK('Hospitalisation Details'!I24),"unkown",'Hospitalisation Details'!I24) -> R1013
A25: Id2312 | B25: 1995 | C25: Oct | D25: 28 | F25: 928.59 | G25: tier - 3 | H25: tier - 1 | I25: R1013 | J25: =IF(ISBLANK('Hospitalisation Details'!I25),"unkown",'Hospitalisation Details'!I25) -> R1013
A26: Id2311 | B26: 2001 | C26: Aug | D26: 19 | F26: 964.71 | G26: tier - 3 | H26: tier - 2 | I26: R1013 | J26: =IF(ISBLANK('Hospitalisation Details'!I26),"unkown",'Hospitalisation Details'!I26) -> R1013
A27: Id2310 | B27: 1994 | C27: Nov | D27: 22 | F27: 1006.65 | G27: tier - 3 | H27: tier - 2 | I27: R1013 | J27: =IF(ISBLANK('Hospitalisation Details'!I27),"unkown",'Hospitalisation Details'!I27) -> R1013
A28: Id2309 | B28: 2000 | C28: Oct | F28: 1012 | G28: tier - 3 | H28: tier - 2 | I28: R1013 | J28: =IF(ISBLANK('Hospitalisation Details'!I28),"unkown",'Hospitalisation Details'!I28) -> R1013
A29: Id2308 | B29: 1999 | C29: Aug | F29: 1019 | G29: tier - 3 | H29: tier - 2 | I29: R1013 | J29: =IF(ISBLANK('Hospitalisation Details'!I29),"unkown",'Hospitalisation Details'!I29) -> R1013
A30: Id2307 | B30: 1995 | C30: Oct | F30: 1033.74 | G30: tier - 3 | H30: tier - 1 | I30: R1013 | J30: =IF(ISBLANK('Hospitalisation Details'!I30),"unkown",'Hospitalisation Details'!I30) -> R1013
A31: Id2306 | B31: 1994 | C31: Nov | D31: 17 | F31: 1044 | G31: tier - 3 | H31: tier - 2 | I31: R1013 | J31: =IF(ISBLANK('Hospitalisation Details'!I31),"unkown",'Hospitalisation Details'!I31) -> R1013
A32: Id2305 | B32: 2002 | C32: Jul | D32: 20 | F32: 1047 | G32: tier - 3 | H32: tier - 1 | I32: R1013 | J32: =IF(ISBLANK('Hospitalisation Details'!I32),"unkown",'Hospitalisation Details'!I32) -> R1013
A33: Id2304 | B33: 2002 | C33: Jul | F33: 1049 | G33: tier - 3 | H33: tier - 2 | I33: R1012 | J33: =IF(ISBLANK('Hospitalisation Details'!I33),"unkown",'Hospitalisation Details'!I33) -> R1012
A34: Id2303 | B34: 1995 | C34: Jun | F34: 1056 | G34: tier - 3 | H34: tier - 2 | I34: R1013 | J34: =IF(ISBLANK('Hospitalisation Details'!I34),"unkown",'Hospitalisation Details'!I34) -> R1013
A35: Id2302 | B35: 1993 | C35: Sep | D35: 28 | F35: 1068 | G35: tier - 3 | H35: tier - 1 | I35: R1013 | J35: =IF(ISBLANK('Hospitalisation Details'!I35),"unkown",'Hospitalisation Details'!I35) -> R1013
A36: Id2301 | B36: 2004 | C36: Aug | D36: 24 | F36: 1070 | G36: tier - 3 | H36: tier - 3 | I36: R1013 | J36: =IF(ISBLANK('Hospitalisation Details'!I36),"unkown",'Hospitalisation Details'!I36) -> R1013
A37: Id2300 | B37: 1997 | C37: Aug | D37: 13 | F37: 1071 | G37: tier - 3 | H37: tier - 3 | I37: R1013 | J37: =IF(ISBLANK('Hospitalisation Details'!I37),"unkown",'Hospitalisation Details'!I37) -> R1013
A38: Id2299 | B38: 1998 | C38: Dec | D38: 26 | F38: 1082 | G38: tier - 3 | H38: tier - 2 | I38: R1013 | J38: =IF(ISBLANK('Hospitalisation Details'!I38),"unkown",'Hospitalisation Details'!I38) -> R1013
A39: Id2298 | B39: 2002 | C39: Aug | D39: 13 | F39: 1086 | G39: tier - 3 | H39: tier - 3 | I39: R1013 | J39: =IF(ISBLANK('Hospitalisation Details'!I39),"unkown",'Hospitalisation Details'!I39) -> R1013
A40: Id2297 | B40: 2004 | C40: Nov | D40: 12 | F40: 1121.87 | G40: tier - 3 | H40: tier - 1 | I40: R1013 | J40: =IF(ISBLANK('Hospitalisation Details'!I40),"unkown",'Hospitalisation Details'!I40) -> R1013
...

Sheet Table3
A1: Customer ID | B1: BMI | C1: HBA1C | D1: Heart Issues | E1: Any Transplants | F1: Cancer history | G1: NumberOfMajorSurgeries | H1: smoker | I1: Weight status
A2: Id1 | B2: 47.41 | C2: 7.47 | D2: No | E2: No | F2: No | G2: 0 | H2: yes | I2: Normal weight
A3: Id2 | B3: 30.36 | C3: 5.77 | D3: No | E3: No | F3: No | G3: 0 | H3: yes | I3: Normal weight
A4: Id3 | B4: 34.485 | C4: 11.87 | D4: yes | E4: No | F4: No | G4: 2 | H4: yes | I4: Normal weight
A5: Id4 | B5: 38.095 | C5: 6.05 | D5: No | E5: No | F5: No | G5: 0 | H5: yes | I5: Normal weight
A6: Id5 | B6: 35.53 | C6: 5.45 | D6: No | E6: No | F6: No | G6: 0 | H6: yes | I6: Normal weight
A7: Id6 | B7: 32.8 | C7: 6.59 | D7: No | E7: No | F7: No | G7: 0 | H7: yes | I7: Normal weight
A8: Id7 | B8: 36.4 | C8: 6.07 | D8: No | E8: No | F8: No | G8: 0 | H8: yes | I8: Normal weight
A9: Id8 | B9: 36.96 | C9: 7.93 | D9: No | E9: No | F9: No | G9: 3 | H9: yes | I9: Normal weight
A10: Id9 | B10: 41.14 | C10: 9.58 | D10: yes | E10: No | F10: Yes | G10: 1 | H10: yes | I10: Normal weight
A11: Id10 | B11: 38.06 | C11: 10.79 | D11: No | E11: No | F11: No | G11: 0 | H11: yes | I11: Normal weight
A12: Id11 | B12: 37.7 | C12: 5.96 | D12: yes | E12: No | F12: No | G12: 2 | H12: yes | I12: Normal weight
A13: Id12 | B13: 42.13 | C13: 11.9 | D13: No | E13: No | F13: No | G13: 0 | H13: yes | I13: Normal weight
... A2336: Id2335 | B2336: 17.58 | C2336: 4.51 | D2336: No | E2336: No | F2336: No | G2336: 1 | H2336: No | I2336: Under weight

Sheet Table3__2
A1: Customer ID | B1: BMI | C1: HBA1C | D1: Heart Issues | E1: Any Transplants | F1: Cancer history | G1: NumberOfMajorSurgeries | H1: smoker | I1: Weight status | J1: Diabetes status
A2: Id1 | B2: 47.41 | C2: 7.47 | D2: No | E2: No | F2: No | G2: 0 | H2: yes | I2: Normal weight | J2: Prediabetes
A3: Id2 | B3: 30.36 | C3: 5.77 | D3: No | E3: No | F3: No | G3: 0 | H3: yes | I3: Normal weight | J3: Diabetes
A4: Id3 | B4: 34.485 | C4: 11.87 | D4: yes | E4: No | F4: No | G4: 2 | H4: yes | I4: Normal weight | J4: Prediabetes
A5: Id4 | B5: 38.095 | C5: 6.05 | D5: No | E5: No | F5: No | G5: 0 | H5: yes | I5: Normal weight | J5: Diabetes
A6: Id5 | B6: 35.53 | C6: 5.45 | D6: No | E6: No | F6: No | G6: 0 | H6: yes | I6: Normal weight | J6: Normal
A7: Id6 | B7: 32.8 | C7: 6.59 | D7: No | E7: No | F7: No | G7: 0 | H7: yes | I7: Normal weight | J7: Prediabetes
A8: Id7 | B8: 36.4 | C8: 6.07 | D8: No | E8: No | F8: No | G8: 0 | H8: yes | I8: Normal weight | J8: Diabetes
A9: Id8 | B9: 36.96 | C9: 7.93 | D9: No | E9: No | F9: No | G9: 3 | H9: yes | I9: Normal weight | J9: Prediabetes
A10: Id9 | B10: 41.14 | C10: 9.58 | D10: yes | E10: No | F10: Yes | G10: 1 | H10: yes | I10: Normal weight | J10: Prediabetes
A11: Id10 | B11: 38.06 | C11: 10.79 | D11: No | E11: No | F11: No | G11: 0 | H11: yes | I11: Normal weight | J11: Prediabetes
A12: Id11 | B12: 37.7 | C12: 5.96 | D12: yes | E12: No | F12: No | G12: 2 | H12: yes | I12: Normal weight | J12: Diabetes
A13: Id12 | B13: 42.13 | C13: 11.9 | D13: No | E13: No | F13: No | G13: 0 | H13: yes | I13: Normal weight | J13: Prediabetes
... A2338: Id2337 | B2338: 115.16776 | C2338: 62.529877 | D2338: yes | E2338: No | F2338: No | G2338: 1 | H2338: yes | I2338: Normal weight | J2338: Normal
G2339: 0
G2340: 1
G2341: 1
G2342: 0
G2343: 1
G2344: 1
G2345: 1
G2346: 1
G2347: 1

Sheet Table3 (2)
A1: Customer ID | B1: BMI | C1: HBA1C | D1: Heart Issues | E1: Any Transplants | F1: Cancer history | G1: NumberOfMajorSurgeries | H1: smoker | I1: Weight status
A2: Id1 | B2: 47.41 | C2: 7.47 | D2: No | E2: No | F2: No | G2: 0 | H2: yes | I2: Normal weight
A3: Id2 | B3: 30.36 | C3: 5.77 | D3: No | E3: No | F3: No | G3: 0 | H3: yes | I3: Normal weight
A4: Id3 | B4: 34.485 | C4: 11.87 | D4: yes | E4: No | F4: No | G4: 2 | H4: yes | I4: Normal weight
A5: Id4 | B5: 38.095 | C5: 6.05 | D5: No | E5: No | F5: No | G5: 0 | H5: yes | I5: Normal weight
A6: Id5 | B6: 35.53 | C6: 5.45 | D6: No | E6: No | F6: No | G6: 0 | H6: yes | I6: Normal weight
A7: Id6 | B7: 32.8 | C7: 6.59 | D7: No | E7: No | F7: No | G7: 0 | H7: yes | I7: Normal weight
A8: Id7 | B8: 36.4 | C8: 6.07 | D8: No | E8: No | F8: No | G8: 0 | H8: yes | I8: Normal weight
A9: Id8 | B9: 36.96 | C9: 7.93 | D9: No | E9: No | F9: No | G9: 3 | H9: yes | I9: Normal weight
A10: Id9 | B10: 41.14 | C10: 9.58 | D10: yes | E10: No | F10: Yes | G10: 1 | H10: yes | I10: Normal weight
A11: Id10 | B11: 38.06 | C11: 10.79 | D11: No | E11: No | F11: No | G11: 0 | H11: yes | I11: Normal weight
A12: Id11 | B12: 37.7 | C12: 5.96 | D12: yes | E12: No | F12: No | G12: 2 | H12: yes | I12: Normal weight
A13: Id12 | B13: 42.13 | C13: 11.9 | D13: No | E13: No | F13: No | G13: 0 | H13: yes | I13: Normal weight
... A2336: Id2335 | B2336: 17.58 | C2336: 4.51 | D2336: No | E2336: No | F2336: No | G2336: 1 | H2336: No | I2336: Under weight

Sheet Medical Examinations
A1: Customer ID | B1: BMI | C1: HBA1C | D1: Heart Issues | E1: Any Transplants | F1: Cancer history | G1: NumberOfMajorSurgeries | H1: smoker | I1: Weight ststus
A2: Id1 | B2: 47.41 | C2: 7.47 | D2: No | E2: No | F2: No | G2: 0 | H2: yes
A3: Id2 | B3: 30.36 | C3: 5.77 | D3: No | E3: No | F3: No | G3: 0 | H3: yes
A4: Id3 | B4: 34.485 | C4: 11.87 | D4: yes | E4: No | F4: No | G4: 2 | H4: yes
A5: Id4 | B5: 38.095 | C5: 6.05 | D5: No | E5: No | F5: No | G5: 0 | H5: yes
A6: Id5 | B6: 35.53 | C6: 5.45 | D6: No | E6: No | F6: No | G6: 0 | H6: yes
A7: Id6 | B7: 32.8 | C7: 6.59 | D7: No | E7: No | F7: No | G7: 0 | H7: yes
A8: Id7 | B8: 36.4 | C8: 6.07 | D8: No | E8: No | F8: No | G8: 0 | H8: yes
A9: Id8 | B9: 36.96 | C9: 7.93 | D9: No | E9: No | F9: No | G9: 3 | H9: yes
A10: Id9 | B10: 41.14 | C10: 9.58 | D10: yes | E10: No | F10: Yes | G10: 1 | H10: yes
A11: Id10 | B11: 38.06 | C11: 10.79 | D11: No | E11: No | F11: No | G11: 0 | H11: yes
A12: Id11 | B12: 37.7 | C12: 5.96 | D12: yes | E12: No | F12: No | G12: 2 | H12: yes
A13: Id12 | B13: 42.13 | C13: 11.9 | D13: No | E13: No | F13: No | G13: 0 | H13: yes
... A2336: Id2335 | B2336: 17.58 | C2336: 4.51 | D2336: No | E2336: No | F2336: No | G2336: 1 | H2336: No

Sheet pivote table
B3: Column Labels
B4: Cancer history | C4: Yes | D4: No | E4: Grand Total
A5: Smoker | B5: 1 | C5: 245 | D5: 2090 | E5: 2336
H11: Column Labels
